<?xml version="1.0"?>
<robot name="LidarRobot1">
<!--base-->
    <!--base_footprint-->
    <link name="base_footprint" />

    <!--base_joint-->
    <joint name="base_joint" type="fixed">
        <origin xyz="0 0 0" rpy="0 0 0" />
        <parent link="base_footprint" />
        <child link="base_link" />
    </joint>

    <!--base_link-->
    <link name="base_link">
        <visual>
            <origin xyz="0 0 0" rpy="0 0 0" />
            <geometry>
                <mesh filename="package://LidarRobot1_description/meshes/LidarRobot1_base.dae" />
            </geometry>
        </visual>

        <collision>
            <origin xyz="0 0 0" rpy="0 0 0" />
            <geometry>
                <mesh filename="package://LidarRobot1_description/meshes/LidarRobot1_base.dae" />
            </geometry>
        </collision>

        <inertial>
            <origin xyz="0 0 0.13" rpy="0 0 0" />
            <mass value="2" />
            <inertia ixx="0.06427" iyy="0.06427" izz="0.12000" ixy="0" ixz="0" iyz="0" /><!--<box size="0.6 0.6 0.16" />-->
        </inertial>
    </link>

    <!--base_gazebo-->
    <gazebo reference="base_link">
        <selfCollide>false</selfCollide>
        <mu1 value="0.5" />
        <mu2 value="0.5" />
    </gazebo>

<!--wheels-->
  <!--left-->
    <!--leftWheel_joint-->
    <joint name="leftWheel_joint" type="continuous">
        <axis xyz="0 1 0" />
        <origin xyz="0.2 0.25 0.07" rpy="0 0 0" />
        <parent link="base_link" />
        <child link="leftWheel_link" />
        <dynamics damping="1" friction="100" />
    </joint>

    <!--leftWheel_link-->
    <link name="leftWheel_link">
        <visual>
            <origin xyz="0 0 0" rpy="0 0 0" />
            <geometry>
                <mesh filename="package://LidarRobot1_description/meshes/LidarRobot1_leftWheel.dae" />
            </geometry>
        </visual>

        <collision>
            <origin xyz="0 0 0" rpy="0 0 0" />
            <geometry>
                <mesh filename="package://LidarRobot1_description/meshes/LidarRobot1_leftWheel.dae" />
            </geometry>
        </collision>

        <inertial>
            <origin xyz="0 0 0" rpy="1.57 0 0" />
            <mass value="0.4" />
            <inertia ixx="0.00070" iyy="0.00070" izz="0.00098" ixy="0" ixz="0" iyz="0" /><!--<cylinder length="0.08" radius="0.07" />-->
        </inertial>
    </link>

    <!--leftWheel_trans-->
    <transmission name="leftWheel_trans">
        <type>transmission_interface/SimpleTransmission</type>
        <joint name="leftWheel_joint">
            <hardwareInterface>hardware_interface/VelocityJointInterface</hardwareInterface>
        </joint>
        <actuator name="leftWheel_motor">
            <hardwareInterface>hardware_interface/VelocityJointInterface</hardwareInterface>
            <mechanicalReduction>30</mechanicalReduction>
        </actuator>
    </transmission>

    <!--leftWheel_gazebo-->
    <gazebo reference="leftWheel_link">
        <selfCollide>false</selfCollide>
        <mu1 value="0.9" />
        <mu2 value="0.9" />
    </gazebo>

  <!--right-->
    <!--rightWheel_joint-->
    <joint name="rightWheel_joint" type="continuous">
        <axis xyz="0 1 0" />
        <origin xyz="0.2 -0.25 0.07" rpy="0 0 0" />
        <parent link="base_link" />
        <child link="rightWheel_link" />
        <dynamics damping="1" friction="100" />
    </joint>

    <!--rightWheel_link-->
    <link name="rightWheel_link">
        <visual>
            <origin xyz="0 0 0" rpy="0 0 3.14" />
            <geometry>
                <mesh filename="package://LidarRobot1_description/meshes/LidarRobot1_leftWheel.dae" />
            </geometry>
        </visual>
        
        <collision>
            <origin xyz="0 0 0" rpy="0 0 3.14" />
            <geometry>
                <mesh filename="package://LidarRobot1_description/meshes/LidarRobot1_leftWheel.dae" />
            </geometry>
        </collision>

        <inertial>
            <origin xyz="0 0 0" rpy="1.57 0 0" />
            <mass value="0.4" />
            <inertia ixx="0.00070" iyy="0.00070" izz="0.00098" ixy="0" ixz="0" iyz="0" /><!--<cylinder length="0.08" radius="0.07" />-->
        </inertial>
    </link>

    <!--rightWheel_trans-->
    <transmission name="rightWheel_trans">
        <type>transmission_interface/SimpleTransmission</type>
        <joint name="rightWheel_joint">
            <hardwareInterface>hardware_interface/VelocityJointInterface</hardwareInterface>
        </joint>
        <actuator name="rightWheel_motor">
            <hardwareInterface>hardware_interface/VelocityJointInterface</hardwareInterface>
            <mechanicalReduction>30</mechanicalReduction>
        </actuator>
    </transmission>

    <!--rightWheel_gazebo-->
    <gazebo reference="rightWheel_link">
        <selfCollide>false</selfCollide>
        <mu1 value="0.9" />
        <mu2 value="0.9" />
    </gazebo>

  <!--rear-->
    <!--trackleWheelConector_joint-->
    <joint name="trackleWheelConector_joint" type="fixed">
        <origin xyz="-0.2 0 0.03" rpy="0 0 0" />
        <parent link="base_link" />
        <child link="trackleWheelConector_link" />
    </joint>

    <!--trackleWheelConector_link-->
    <link name="trackleWheelConector_link">
        <visual>
            <origin xyz="0 0 0" rpy="0 0 0" />
            <geometry>
                <mesh filename="package://LidarRobot1_description/meshes/LidarRobot1_trackleWheelConector.dae" />
            </geometry>
        </visual>

        <collision>
            <origin xyz="0 0 0" rpy="0 0 0" />
            <geometry>
                <mesh filename="package://LidarRobot1_description/meshes/LidarRobot1_trackleWheelConector.dae" />
            </geometry>
        </collision>

        <inertial>
            <origin xyz="0 0 0" rpy="0 0 0" />
            <mass value="0.1" />
            <inertia ixx="0.00009" iyy="0.00009" izz="0.00002" ixy="0" ixz="0" iyz="0" /><!--<cylinder length="0.1" radius="0.02" />-->
        </inertial>
    </link>

    <!--trackleWheelConector_gazebo-->
    <gazebo reference="trackleWheelConector_link">
        <selfCollide>false</selfCollide>
        <mu1 value="0.5" />
        <mu2 value="0.5" />
    </gazebo>

    <!--trackleWheel_joint-->
    <joint name="trackleWheel_joint" type="fixed">
        <origin xyz="0 0 0" rpy="0 0 0" />
        <parent link="trackleWheelConector_link" />
        <child link="trackleWheel_link" />
    </joint>

    <!--trackleWheel_link-->
    <link name="trackleWheel_link">
        <visual>
            <origin xyz="0 0 0" rpy="0 0 0" />
            <geometry>
                <mesh filename="package://LidarRobot1_description/meshes/LidarRobot1_trackleWheel.dae" />
            </geometry>
        </visual>
        
        <collision>
            <origin xyz="0 0 0" rpy="0 0 0" />
            <geometry>
                <sphere radius="0.03" />
            </geometry>
        </collision>

        <inertial>
            <origin xyz="0 0 0" rpy="1.57 0 0" />
            <mass value="0.2" />
            <inertia ixx="0.00007" iyy="0.00007" izz="0.00009" ixy="0" ixz="0" iyz="0" /><!--<cylinder length="0.04" radius="0.03" />-->
        </inertial>
    </link>

    <!--trackleWheel_gazebo-->
    <gazebo reference="trackleWheel_link">
        <selfCollide>false</selfCollide>
        <mu1 value="0.1" />
        <mu2 value="0.1" />
    </gazebo>

<!--sensors-->
  <!--lrf-->
    <!--lrf_joint-->
    <joint name="lrf_joint" type="fixed">
        <origin xyz="0.24 0 0.245" rpy="0 0 0" />
        <parent link="base_link" />
        <child link="lrf_link" />
    </joint>

    <!--lrf_link-->
    <link name="lrf_link">
        <visual>
            <origin xyz="0 0 0" rpy="0 0 0" />
            <geometry>
                <mesh filename="package://LidarRobot1_description/meshes/LidarRobot1_lrf.dae" />
            </geometry>
        </visual>

        <collision>
            <origin xyz="0 0 0" rpy="0 0 0" />
            <geometry>
                <mesh filename="package://LidarRobot1_description/meshes/LidarRobot1_lrf.dae" />
            </geometry>
        </collision>

        <inertial>
            <origin xyz="0 0 0" rpy="0 0 0" />
            <mass value="0.4" />
            <inertia ixx="0.00023" iyy="0.00023" izz="0.00013" ixy="0" ixz="0" iyz="0" /><!--<cylinder length="0.07" radius="0.025" />-->
        </inertial>
    </link>

    <!--lrf_gazebo-->
    <gazebo reference="lrf_link">
        <selfCollide>false</selfCollide>
        <mu1 value="0.5" />
        <mu2 value="0.5" />

        <sensor type="ray" name="lrf_sensor">
            <pose>0 0 0 0 0 0</pose>
            <visualize>true</visualize>
            <update_rate>40</update_rate>
            <ray>
                <scan>
                    <horizontal>
                        <samples>720</samples>
                        <resolution>1</resolution>
                        <min_angle>-3.14</min_angle> <!--defined in rad-->
                        <max_angle>3.14</max_angle> <!--defined in rad-->
                    </horizontal>
                </scan>
                <range>
                    <min>0.1</min>
                    <max>60</max>
                    <resolution>0.01</resolution>
                </range>
                <noise>
                    <type>gaussian</type>
                    <mean>0</mean>
                    <stddev>0.03</stddev>
                </noise>
            </ray>
            <plugin name="gazebo_ros_lrf_controller" filename="libgazebo_ros_laser.so">
                <topicName>/scan</topicName>
                <frameName>lrf_link</frameName>
            </plugin>
        </sensor>
    </gazebo>

<!--gazebo-->
    <!--gazebo_plugin-->
    <gazebo>
        <plugin name="gazebo_ros_control" filename="libgazebo_ros_control.so">
            <robotNamespace>/LidarRobot1</robotNamespace>
            <robotSimType>gazebo_ros_control/DefaultRobotHWSim</robotSimType>
            <legacyModeNS>true</legacyModeNS>
        </plugin>
    </gazebo>
</robot>